<?xml version="1.0" encoding="utf-8"?>

<!-- 
    Title:
      Open Source Rover (OSR) Model geometry

    Description:
      This contains the geometry for the links and joints of the rover.
      Meshes are from https://github.com/nasa-jpl/open-source-rover.

    Version:
      v1.0.0, 03/2023
      
    Tested with:
      ROS Noetic
      Linux Ubuntu, 20.04 LTS

    References:
      - corner-motor-datasheet (pdf)
      - drive-motor-datasheet (pdf)
-->

<!-- **************** Model geometry for OSR **************** -->
<robot
  xmlns:xacro="http://ros.org/wiki/xacro"
  name="osr_geometry">

  <!-- Load parameter values from parameter file -->
  <xacro:property name="yaml_file" value="$(find osr)/config/osr_parameters.yaml" />
  <xacro:property name="yaml_dict" value="${xacro.load_yaml(yaml_file)}"/>
  <xacro:property name="steer_angle_max" value="${yaml_dict['steer_angle_max']}" />
  <xacro:property name="steer_angle_min" value="${yaml_dict['steer_angle_min']}" />
  <xacro:property name="steer_effort_max" value="${yaml_dict['steer_effort_max']}" />
  <xacro:property name="steer_vel_max" value="${yaml_dict['steer_vel_max']}" />
  <xacro:property name="drive_effort_max" value="${yaml_dict['drive_effort_max']}" />
  <xacro:property name="drive_vel_max" value="${yaml_dict['drive_vel_max']}" />
  
  <link
    name="base_footprint">
  </link>
  <joint name="base_footprint_to_link" type="fixed">
    <parent link="base_footprint"/>
    <child link="base_link"/>
    <origin
        xyz="0 0 0.4"
        rpy="0 0 0" />
  </joint>

  <xacro:mimic_joint_plugin_gazebo 
    name_prefix="left_rocker_joint"
    parent_joint="right_rocker_joint"
    mimic_joint="left_rocker_joint"
    has_pid="false"
    multiplier="-1.0"
    max_effort="1000.0" />

  <!-- **************** Geometry generated by Solidworks URDF exporter **************** -->
  <link
    name="base_link">
    <inertial>
      <origin
        xyz="-0.16002 -0.00015951 -0.059815"
        rpy="0 0 0" />
      <mass
        value="1.3874" />
      <inertia
        ixx="0.0060646"
        ixy="3.4445E-11"
        ixz="-3.7962E-09"
        iyy="0.008315"
        iyz="-3.0768E-05"
        izz="0.013019" />
    </inertial>
    <visual>
      <origin
        xyz="0 0 0"
        rpy="0 0 0" />
      <geometry>
        <mesh
          filename="package://osr/meshes/base_link.STL" />
      </geometry>
      <material
        name="">
        <color
          rgba="0.89804 0.91765 0.92941 1" />
      </material>
    </visual>
    <collision>
      <origin
        xyz="0 0 0"
        rpy="0 0 0" />
      <geometry>
        <mesh
          filename="package://osr/meshes/base_link.STL" />
      </geometry>
    </collision>
  </link>
  <link
    name="left_rocker">
    <inertial>
      <origin
        xyz="-0.081315 0.0093907 -0.033982"
        rpy="0 0 0" />
      <mass
        value="0.54518" />
      <inertia
        ixx="0.00030463"
        ixy="-5.98E-05"
        ixz="-7.683E-08"
        iyy="0.00071766"
        iyz="-8.8606E-07"
        izz="0.0008578" />
    </inertial>
    <visual>
      <origin
        xyz="0 0 0"
        rpy="0 0 0" />
      <geometry>
        <mesh
          filename="package://osr/meshes/left_rocker.STL" />
      </geometry>
      <material
        name="">
        <color
          rgba="0.89804 0.91765 0.92941 1" />
      </material>
    </visual>
    <collision>
      <origin
        xyz="0 0 0"
        rpy="0 0 0" />
      <geometry>
        <mesh
          filename="package://osr/meshes/left_rocker.STL" />
      </geometry>
    </collision>
  </link>
  <joint
    name="left_rocker_joint"
    type="revolute">
    <origin
      xyz="-0.173744384181607 0.190500000000003 -0.0594359999999901"
      rpy="-1.57079632679489 0 0" />
    <parent
      link="base_link" />
    <child
      link="left_rocker" />
    <axis
      xyz="0 0 1" />
    <limit
      lower="-0.1"
      upper="0.1"
      effort="0"
      velocity="0" />
    <mimic
      joint="right_rocker_joint"
      multiplier="-1"
      offset="0" />
  </joint>
  <link
    name="left_bogie">
    <inertial>
      <origin
        xyz="0.11235 -0.038605 0.3532"
        rpy="0 0 0" />
      <mass
        value="0.5727" />
      <inertia
        ixx="0.0003158"
        ixy="7.6325E-05"
        ixz="3.8116E-08"
        iyy="0.00032094"
        iyz="8.1411E-07"
        izz="0.00046244" />
    </inertial>
    <visual>
      <origin
        xyz="0 0 0"
        rpy="0 0 0" />
      <geometry>
        <mesh
          filename="package://osr/meshes/left_bogie.STL" />
      </geometry>
      <material
        name="">
        <color
          rgba="0.89804 0.91765 0.92941 1" />
      </material>
    </visual>
    <collision>
      <origin
        xyz="0 0 0"
        rpy="0 0 0" />
      <geometry>
        <mesh
          filename="package://osr/meshes/left_bogie.STL" />
      </geometry>
    </collision>
  </link>
  <joint
    name="left_lb_axis"
    type="continuous">
    <origin
      xyz="0.187139225679552 0.102147968996281 -0.38522275000001"
      rpy="0 0 0" />
    <parent
      link="left_rocker" />
    <child
      link="left_bogie" />
    <axis
      xyz="0 0 -0.999999999999994" />
    <limit
      lower="0"
      upper="0"
      effort="0"
      velocity="0" />
  </joint>
  <link
    name="front_left_corner">
    <inertial>
      <origin
        xyz="-0.00021559 -0.058703 -0.078963"
        rpy="0 0 0" />
      <mass
        value="0.17725" />
      <inertia
        ixx="0.00012121"
        ixy="8.0199E-08"
        ixz="1.5423E-07"
        iyy="7.6277E-05"
        iyz="7.7454E-08"
        izz="0.00011786" />
    </inertial>
    <visual>
      <origin
        xyz="0 0 0"
        rpy="0 0 0" />
      <geometry>
        <mesh
          filename="package://osr/meshes/front_left_corner.STL" />
      </geometry>
      <material
        name="">
        <color
          rgba="0.89804 0.91765 0.92941 1" />
      </material>
    </visual>
    <collision>
      <origin
        xyz="0 0 0"
        rpy="0 0 0" />
      <geometry>
        <mesh
          filename="package://osr/meshes/front_left_corner.STL" />
      </geometry>
    </collision>
  </link>
  <joint
    name="front_left_corner_joint"
    type="revolute">
    <origin
      xyz="0.215421536981298 0.00545134107835665 0.351039494185675"
      rpy="1.57079621520304 0 0" />
    <parent
      link="left_bogie" />
    <child
      link="front_left_corner" />
    <axis
      xyz="0 0 -0.999999999999988" />
    <limit
      lower="${steer_angle_min}"
      upper="${steer_angle_max}"
      effort="${steer_effort_max}"
      velocity="${steer_vel_max}" />
  </joint>
  <link
    name="front_left_wheel">
    <inertial>
      <origin
        xyz="-8.2916E-07 -1.7142E-07 0.00092227"
        rpy="0 0 0" />
      <mass
        value="1.4215" />
      <inertia
        ixx="0.0038879"
        ixy="9.182E-08"
        ixz="1.0732E-07"
        iyy="0.003888"
        iyz="-7.856E-08"
        izz="0.0058222" />
    </inertial>
    <visual>
      <origin
        xyz="0 0 0"
        rpy="0 0 0" />
      <geometry>
        <mesh
          filename="package://osr/meshes/front_left_wheel.STL" />
      </geometry>
      <material
        name="">
        <color
          rgba="0.29412 0.29412 0.29412 1" />
      </material>
    </visual>
    <collision>
      <origin
        xyz="0 0 0"
        rpy="0 0 0" />
      <geometry>
        <mesh
          filename="package://osr/meshes/front_left_wheel.STL" />
      </geometry>
    </collision>
  </link>
  <joint
    name="front_left_drive_joint"
    type="continuous">
    <origin
      xyz="-0.00017181 -4.3245E-05 -0.12889"
      rpy="-1.5708 0 0" />
    <parent
      link="front_left_corner" />
    <child
      link="front_left_wheel" />
    <axis
      xyz="0 0 1" />
    <limit
      effort="${drive_effort_max}"
      velocity="${drive_vel_max}"/>
  </joint>
  <link
    name="middle_left_wheel">
    <inertial>
      <origin
        xyz="-8.2252E-07 -2.0291E-07 0.00092227"
        rpy="0 0 0" />
      <mass
        value="1.4215" />
      <inertia
        ixx="0.0038879"
        ixy="8.7004E-08"
        ixz="1.1027E-07"
        iyy="0.003888"
        iyz="-7.439E-08"
        izz="0.0058222" />
    </inertial>
    <visual>
      <origin
        xyz="0 0 0"
        rpy="0 0 0" />
      <geometry>
        <mesh
          filename="package://osr/meshes/middle_left_wheel.STL" />
      </geometry>
      <material
        name="">
        <color
          rgba="0.29412 0.29412 0.29412 1" />
      </material>
    </visual>
    <collision>
      <origin
        xyz="0 0 0"
        rpy="0 0 0" />
      <geometry>
        <mesh
          filename="package://osr/meshes/middle_left_wheel.STL" />
      </geometry>
    </collision>
  </link>
  <joint
    name="middle_left_drive_joint"
    type="continuous">
    <origin
      xyz="-0.063913345312238 0.103041664281169 0.436572914004881"
      rpy="0 0 0" />
    <parent
      link="left_bogie" />
    <child
      link="middle_left_wheel" />
    <axis
      xyz="0 0 1" />
    <limit
      effort="${drive_effort_max}"
      velocity="${drive_vel_max}"/>
  </joint>
  <link
    name="back_left_corner">
    <inertial>
      <origin
        xyz="0.00012803 -0.058617 -0.078963"
        rpy="0 0 0" />
      <mass
        value="0.17725" />
      <inertia
        ixx="0.00012121"
        ixy="8.0199E-08"
        ixz="1.5423E-07"
        iyy="7.6277E-05"
        iyz="7.7454E-08"
        izz="0.00011786" />
    </inertial>
    <visual>
      <origin
        xyz="0 0 0"
        rpy="0 0 0" />
      <geometry>
        <mesh
          filename="package://osr/meshes/back_left_corner.STL" />
      </geometry>
      <material
        name="">
        <color
          rgba="0.89804 0.91765 0.92941 1" />
      </material>
    </visual>
    <collision>
      <origin
        xyz="0 0 0"
        rpy="0 0 0" />
      <geometry>
        <mesh
          filename="package://osr/meshes/back_left_corner.STL" />
      </geometry>
    </collision>
  </link>
  <joint
    name="back_left_corner_joint"
    type="revolute">
    <origin
      xyz="-0.186901909356396 0.0959973702109308 -0.0342697447940019"
      rpy="1.57079632679489 0 -0.0409113907910423" />
    <parent
      link="left_rocker" />
    <child
      link="back_left_corner" />
    <axis
      xyz="0 0 -1" />
    <limit
      lower="${steer_angle_min}"
      upper="${steer_angle_max}"
      effort="${steer_effort_max}"
      velocity="${steer_vel_max}" />
  </joint>
  <link
    name="back_left_wheel">
    <inertial>
      <origin
        xyz="-8.2953E-07 -1.7315E-07 0.00092227"
        rpy="0 0 0" />
      <mass
        value="1.4215" />
      <inertia
        ixx="0.0038879"
        ixy="9.1817E-08"
        ixz="1.0732E-07"
        iyy="0.003888"
        iyz="-7.8477E-08"
        izz="0.0058222" />
    </inertial>
    <visual>
      <origin
        xyz="0 0 0"
        rpy="0 0 0" />
      <geometry>
        <mesh
          filename="package://osr/meshes/back_left_wheel.STL" />
      </geometry>
      <material
        name="">
        <color
          rgba="0.29412 0.29412 0.29412 1" />
      </material>
    </visual>
    <collision>
      <origin
        xyz="0 0 0"
        rpy="0 0 0" />
      <geometry>
        <mesh
          filename="package://osr/meshes/back_left_wheel.STL" />
      </geometry>
    </collision>
  </link>
  <joint
    name="back_left_drive_joint"
    type="continuous">
    <origin
      xyz="0.00017181 4.3245E-05 -0.12889"
      rpy="-1.5708 0 0" />
    <parent
      link="back_left_corner" />
    <child
      link="back_left_wheel" />
    <axis
      xyz="0 0 1" />
    <limit
      effort="${drive_effort_max}"
      velocity="${drive_vel_max}"/>
  </joint>
  <link
    name="right_rocker">
    <inertial>
      <origin
        xyz="-0.081411 0.0085199 0.034486"
        rpy="0 0 0" />
      <mass
        value="0.54518" />
      <inertia
        ixx="0.00030593"
        ixy="-6.4225E-05"
        ixz="-6.7388E-08"
        iyy="0.00071636"
        iyz="-8.868E-07"
        izz="0.0008578" />
    </inertial>
    <visual>
      <origin
        xyz="0 0 0"
        rpy="0 0 0" />
      <geometry>
        <mesh
          filename="package://osr/meshes/right_rocker.STL" />
      </geometry>
      <material
        name="">
        <color
          rgba="0.89804 0.91765 0.92941 1" />
      </material>
    </visual>
    <collision>
      <origin
        xyz="0 0 0"
        rpy="0 0 0" />
      <geometry>
        <mesh
          filename="package://osr/meshes/right_rocker.STL" />
      </geometry>
    </collision>
  </link>
  <joint
    name="right_rocker_joint"
    type="revolute">
    <origin
      xyz="-0.17374 -0.1905 -0.059436"
      rpy="-1.5708 0 0" />
    <parent
      link="base_link" />
    <child
      link="right_rocker" />
    <axis
      xyz="0 0 1" />
    <limit
      lower="-0.1"
      upper="0.1"
      effort="0"
      velocity="0" />
  </joint>
  <link
    name="right_bogie">
    <inertial>
      <origin
        xyz="0.10915 -0.034095 -0.35298"
        rpy="0 0 0" />
      <mass
        value="0.5756" />
      <inertia
        ixx="0.00031636"
        ixy="7.664E-05"
        ixz="3.8372E-08"
        iyy="0.00032122"
        iyz="9.6233E-07"
        izz="0.00046272" />
    </inertial>
    <visual>
      <origin
        xyz="0 0 0"
        rpy="0 0 0" />
      <geometry>
        <mesh
          filename="package://osr/meshes/right_bogie.STL" />
      </geometry>
      <material
        name="">
        <color
          rgba="0.89804 0.91765 0.92941 1" />
      </material>
    </visual>
    <collision>
      <origin
        xyz="0 0 0"
        rpy="0 0 0" />
      <geometry>
        <mesh
          filename="package://osr/meshes/right_bogie.STL" />
      </geometry>
    </collision>
  </link>
  <joint
    name="right_rb_axis"
    type="continuous">
    <origin
      xyz="0.188216644575796 0.100148826719136 0.384524249999983"
      rpy="0 0 0" />
    <parent
      link="right_rocker" />
    <child
      link="right_bogie" />
    <axis
      xyz="0 0 -0.999999999994781" />
    <limit
      lower="0"
      upper="0"
      effort="0"
      velocity="0" />
  </joint>
  <link
    name="front_right_corner">
    <inertial>
      <origin
        xyz="-0.00027466 0.05974 -0.078145"
        rpy="0 0 0" />
      <mass
        value="0.1709" />
      <inertia
        ixx="0.00011992"
        ixy="8.0199E-08"
        ixz="-1.5237E-07"
        iyy="7.3812E-05"
        iyz="-7.749E-08"
        izz="0.00011672" />
    </inertial>
    <visual>
      <origin
        xyz="0 0 0"
        rpy="0 0 0" />
      <geometry>
        <mesh
          filename="package://osr/meshes/front_right_corner.STL" />
      </geometry>
      <material
        name="">
        <color
          rgba="0.89804 0.91765 0.92941 1" />
      </material>
    </visual>
    <collision>
      <origin
        xyz="0 0 0"
        rpy="0 0 0" />
      <geometry>
        <mesh
          filename="package://osr/meshes/front_right_corner.STL" />
      </geometry>
    </collision>
  </link>
  <joint
    name="front_right_corner_joint"
    type="revolute">
    <origin
      xyz="0.213266684003467 0.00945072449948589 -0.350254474673649"
      rpy="1.57079955767686 0 0" />
    <parent
      link="right_bogie" />
    <child
      link="front_right_corner" />
    <axis
      xyz="0 0 -1" />
    <limit
      lower="${steer_angle_min}"
      upper="${steer_angle_max}"
      effort="${steer_effort_max}"
      velocity="${steer_vel_max}" />
  </joint>
  <link
    name="front_right_wheel">
    <inertial>
      <origin
        xyz="8.296E-07 -1.7167E-07 -0.00092227"
        rpy="0 0 0" />
      <mass
        value="1.4215" />
      <inertia
        ixx="0.0038879"
        ixy="-9.1827E-08"
        ixz="1.0729E-07"
        iyy="0.003888"
        iyz="7.8574E-08"
        izz="0.0058222" />
    </inertial>
    <visual>
      <origin
        xyz="0 0 0"
        rpy="0 0 0" />
      <geometry>
        <mesh
          filename="package://osr/meshes/front_right_wheel.STL" />
      </geometry>
      <material
        name="">
        <color
          rgba="0.29412 0.29412 0.29412 1" />
      </material>
    </visual>
    <collision>
      <origin
        xyz="0 0 0"
        rpy="0 0 0" />
      <geometry>
        <mesh
          filename="package://osr/meshes/front_right_wheel.STL" />
      </geometry>
    </collision>
  </link>
  <joint
    name="front_right_drive_joint"
    type="continuous">
    <origin
      xyz="-0.000171808840734172 -4.32447939935077E-05 -0.128892240205189"
      rpy="-1.57079632679494 0 0" />
    <parent
      link="front_right_corner" />
    <child
      link="front_right_wheel" />
    <axis
      xyz="0 0 1" />
    <limit
      effort="${drive_effort_max}"
      velocity="${drive_vel_max}"/>
  </joint>
  <link
    name="middle_right_wheel">
    <inertial>
      <origin
        xyz="8.2244E-07 -2.0285E-07 -0.00092227"
        rpy="0 0 0" />
      <mass
        value="1.4215" />
      <inertia
        ixx="0.0038879"
        ixy="-8.7002E-08"
        ixz="1.1027E-07"
        iyy="0.003888"
        iyz="7.4394E-08"
        izz="0.0058222" />
    </inertial>
    <visual>
      <origin
        xyz="0 0 0"
        rpy="0 0 0" />
      <geometry>
        <mesh
          filename="package://osr/meshes/middle_right_wheel.STL" />
      </geometry>
      <material
        name="">
        <color
          rgba="0.29412 0.29412 0.29412 1" />
      </material>
    </visual>
    <collision>
      <origin
        xyz="0 0 0"
        rpy="0 0 0" />
      <geometry>
        <mesh
          filename="package://osr/meshes/middle_right_wheel.STL" />
      </geometry>
    </collision>
  </link>
  <joint
    name="middle_right_drive_joint"
    type="continuous">
    <origin
      xyz="-0.0660681982900923 0.107041314784848 -0.435874079667899"
      rpy="0 0 0" />
    <parent
      link="right_bogie" />
    <child
      link="middle_right_wheel" />
    <axis
      xyz="0 0 1" />
    <limit
      effort="${drive_effort_max}"
      velocity="${drive_vel_max}"/>
  </joint>
  <link
    name="back_right_corner">
    <inertial>
      <origin
        xyz="6.896E-05 0.059827 -0.078145"
        rpy="0 0 0" />
      <mass
        value="0.1709" />
      <inertia
        ixx="0.00011992"
        ixy="8.0199E-08"
        ixz="-1.5237E-07"
        iyy="7.3812E-05"
        iyz="-7.749E-08"
        izz="0.00011672" />
    </inertial>
    <visual>
      <origin
        xyz="0 0 0"
        rpy="0 0 0" />
      <geometry>
        <mesh
          filename="package://osr/meshes/back_right_corner.STL" />
      </geometry>
      <material
        name="">
        <color
          rgba="0.89804 0.91765 0.92941 1" />
      </material>
    </visual>
    <collision>
      <origin
        xyz="0 0 0"
        rpy="0 0 0" />
      <geometry>
        <mesh
          filename="package://osr/meshes/back_right_corner.STL" />
      </geometry>
    </collision>
  </link>
  <joint
    name="back_right_corner_joint"
    type="revolute">
    <origin
      xyz="-0.187913842817314 0.094001098323477 0.0341832552059909"
      rpy="1.57079632679489 0 -0.0302594744810847" />
    <parent
      link="right_rocker" />
    <child
      link="back_right_corner" />
    <axis
      xyz="0 0 -1" />
    <limit
      lower="${steer_angle_min}"
      upper="${steer_angle_max}"
      effort="${steer_effort_max}"
      velocity="${steer_vel_max}" />
  </joint>
  <link
    name="back_right_wheel">
    <inertial>
      <origin
        xyz="8.2926E-07 -1.7115E-07 -0.00092227"
        rpy="0 0 0" />
      <mass
        value="1.4215" />
      <inertia
        ixx="0.0038879"
        ixy="-9.1814E-08"
        ixz="1.0731E-07"
        iyy="0.003888"
        iyz="7.8576E-08"
        izz="0.0058222" />
    </inertial>
    <visual>
      <origin
        xyz="0 0 0"
        rpy="0 0 0" />
      <geometry>
        <mesh
          filename="package://osr/meshes/back_right_wheel.STL" />
      </geometry>
      <material
        name="">
        <color
          rgba="0.29412 0.29412 0.29412 1" />
      </material>
    </visual>
    <collision>
      <origin
        xyz="0 0 0"
        rpy="0 0 0" />
      <geometry>
        <mesh
          filename="package://osr/meshes/back_right_wheel.STL" />
      </geometry>
    </collision>
  </link>
  <joint
    name="back_right_drive_joint"
    type="continuous">
    <origin
      xyz="0.000171808840750409 4.32447939860969E-05 -0.128892240205184"
      rpy="-1.57079632679494 0 0" />
    <parent
      link="back_right_corner" />
    <child
      link="back_right_wheel" />
    <axis
      xyz="0 0 1" />
    <limit
      effort="${drive_effort_max}"
      velocity="${drive_vel_max}"/>
  </joint>

</robot>
