<?xml version="1.0" encoding="utf-8"?>

<!-- 
    Title:
      Open Source Rover (OSR) Model geometry

    Description:
      This contains the geometry for the links and joints of the rover.
      Meshes are from https://github.com/nasa-jpl/open-source-rover.

    Version:
      v1.1.0, 04/2023
      
    Tested with:
      ROS Noetic
      Linux Ubuntu, 20.04 LTS

    References:
      - corner-motor-datasheet (pdf)
      - drive-motor-datasheet (pdf)
-->

<!-- **************** Model geometry for OSR **************** -->
<robot
  xmlns:xacro="http://ros.org/wiki/xacro"
  name="osr_geometry">

  <!-- Load parameter values from parameter file -->
  <xacro:property name="steer_angle_max" value="${yaml_dict['steer_angle_max']}" />
  <xacro:property name="steer_angle_min" value="${yaml_dict['steer_angle_min']}" />
  <xacro:property name="steer_effort_max" value="${yaml_dict['steer_effort_max']}" />
  <xacro:property name="steer_vel_max" value="${yaml_dict['steer_vel_max']}" />
  <xacro:property name="drive_effort_max" value="${yaml_dict['drive_effort_max']}" />
  <xacro:property name="drive_vel_max" value="${yaml_dict['drive_vel_max']}" />
  <xacro:property name="rocker_limit_upper" value="${yaml_dict['rocker_limit_upper']}" />
  <xacro:property name="rocker_limit_lower" value="${yaml_dict['rocker_limit_lower']}" />
  
  <link
    name="base_footprint">
  </link>
  <joint name="base_footprint_to_link" type="fixed">
    <parent link="base_footprint"/>
    <child link="base_link"/>
    <origin
        xyz="0 0 0.4"
        rpy="0 0 0" />
  </joint>

  <xacro:mimic_joint_plugin_gazebo 
    name_prefix="left_rocker_joint"
    parent_joint="right_rocker_joint"
    mimic_joint="left_rocker_joint"
    has_pid="false"
    multiplier="-1.0"
    max_effort="1000.0" />

  <!-- **************** Geometry generated by Solidworks URDF exporter **************** -->
  <link
    name="base_link">
    <inertial>
      <origin
        xyz="-0.14756 -6.6173E-06 -0.048928"
        rpy="0 0 0" />
      <mass
        value="1.9413" />
      <inertia
        ixx="0.0077101"
        ixy="2.0608E-08"
        ixz="9.3168E-08"
        iyy="0.011398"
        iyz="-3.7258E-09"
        izz="0.017109" />
    </inertial>
    <visual>
      <origin
        xyz="0 0 0"
        rpy="0 0 0" />
      <geometry>
        <mesh
          filename="package://osr/meshes/base_link.STL" />
      </geometry>
      <material
        name="">
        <color
          rgba="0.89804 0.91765 0.92941 1" />
      </material>
    </visual>
    <collision>
      <origin
        xyz="0 0 0"
        rpy="0 0 0" />
      <geometry>
        <mesh
          filename="package://osr/meshes/base_link.STL" />
      </geometry>
    </collision>
  </link>
  <link
    name="left_rocker">
    <inertial>
      <origin
        xyz="0.0093907 -0.081315 0.033982"
        rpy="0 0 0" />
      <mass
        value="0.54518" />
      <inertia
        ixx="0.00071766"
        ixy="-5.98E-05"
        ixz="8.8606E-07"
        iyy="0.00030463"
        iyz="7.6825E-08"
        izz="0.0008578" />
    </inertial>
    <visual>
      <origin
        xyz="0 0 0"
        rpy="0 0 0" />
      <geometry>
        <mesh
          filename="package://osr/meshes/left_rocker.STL" />
      </geometry>
      <material
        name="">
        <color
          rgba="0.89804 0.91765 0.92941 1" />
      </material>
    </visual>
    <collision>
      <origin
        xyz="0 0 0"
        rpy="0 0 0" />
      <geometry>
        <mesh
          filename="package://osr/meshes/left_rocker.STL" />
      </geometry>
    </collision>
  </link>
  <joint
    name="left_rocker_joint"
    type="revolute">
    <origin
      xyz="-0.173736 0.190375827761485 -0.0594359999999915"
      rpy="1.57079632679488 1.5707963267949 0" />
    <parent
      link="base_link" />
    <child
      link="left_rocker" />
    <axis
      xyz="0 0 -1" />
    <limit
      lower="-0.1"
      upper="0.1"
      effort="0"
      velocity="0" />
    <mimic
      joint="right_rocker_joint"
      multiplier="-1"
      offset="0" />
  </joint>
  <link
    name="left_bogie">
    <inertial>
      <origin
        xyz="0.11231 -0.038529 0.35308"
        rpy="0 0 0" />
      <mass
        value="0.5727" />
      <inertia
        ixx="0.0003158"
        ixy="7.6325E-05"
        ixz="3.8124E-08"
        iyy="0.00032094"
        iyz="8.1409E-07"
        izz="0.00046244" />
    </inertial>
    <visual>
      <origin
        xyz="0 0 0"
        rpy="0 0 0" />
      <geometry>
        <mesh
          filename="package://osr/meshes/left_bogie.STL" />
      </geometry>
      <material
        name="">
        <color
          rgba="0.89804 0.91765 0.92941 1" />
      </material>
    </visual>
    <collision>
      <origin
        xyz="0 0 0"
        rpy="0 0 0" />
      <geometry>
        <mesh
          filename="package://osr/meshes/left_bogie.STL" />
      </geometry>
    </collision>
  </link>
  <joint
    name="left_lb_axis"
    type="continuous">
    <origin
      xyz="0.102072501603827 0.187180386097456 0.38509857776149"
      rpy="-3.14159263778426 0 1.57079617385391" />
    <parent
      link="left_rocker" />
    <child
      link="left_bogie" />
    <axis
      xyz="0 0 -1" />
    <limit
      lower="0"
      upper="0"
      effort="0"
      velocity="0" />
  </joint>
  <link
    name="front_left_corner">
    <inertial>
      <origin
        xyz="-0.00021559 -0.058703 -0.078963"
        rpy="0 0 0" />
      <mass
        value="0.17725" />
      <inertia
        ixx="0.00012121"
        ixy="8.0199E-08"
        ixz="1.5423E-07"
        iyy="7.6277E-05"
        iyz="7.7454E-08"
        izz="0.00011786" />
    </inertial>
    <visual>
      <origin
        xyz="0 0 0"
        rpy="0 0 0" />
      <geometry>
        <mesh
          filename="package://osr/meshes/front_left_corner.STL" />
      </geometry>
      <material
        name="">
        <color
          rgba="0.89804 0.91765 0.92941 1" />
      </material>
    </visual>
    <collision>
      <origin
        xyz="0 0 0"
        rpy="0 0 0" />
      <geometry>
        <mesh
          filename="package://osr/meshes/front_left_corner.STL" />
      </geometry>
    </collision>
  </link>
  <joint
    name="front_left_corner_joint"
    type="revolute">
    <origin
      xyz="0.215380376567892 0.00552677512849714 0.350915322468129"
      rpy="1.57079631098936 0 0" />
    <parent
      link="left_bogie" />
    <child
      link="front_left_corner" />
    <axis
      xyz="0 0 -0.999999999999988" />
    <limit
      lower="${steer_angle_min}"
      upper="${steer_angle_max}"
      effort="${steer_effort_max}"
      velocity="${steer_vel_max}" />
  </joint>
  <link
    name="front_left_wheel">
    <inertial>
      <origin
        xyz="4.9366E-10 -1.3882E-10 0.0071368"
        rpy="0 0 0" />
      <mass
        value="0.61431" />
      <inertia
        ixx="0.0011197"
        ixy="5.7673E-08"
        ixz="-3.3832E-16"
        iyy="0.0011199"
        iyz="5.6789E-17"
        izz="0.001892" />
    </inertial>
    <visual>
      <origin
        xyz="0 0 0"
        rpy="0 0 0" />
      <geometry>
        <mesh
          filename="package://osr/meshes/front_left_wheel.STL" />
      </geometry>
      <material
        name="">
        <color
          rgba="0.62745 0.62745 0.62745 1" />
      </material>
    </visual>
    <collision>
      <origin
        xyz="0 0 0"
        rpy="0 0 0" />
      <geometry>
        <mesh
          filename="package://osr/meshes/front_left_wheel.STL" />
      </geometry>
    </collision>
  </link>
  <joint
    name="front_left_drive_joint"
    type="continuous">
    <origin
      xyz="-0.00017180884072221 -4.3244793997782E-05 -0.128892240205177"
      rpy="-1.57079632679486 0 0" />
    <parent
      link="front_left_corner" />
    <child
      link="front_left_wheel" />
    <axis
      xyz="0 0 1" />
    <limit
      effort="${drive_effort_max}"
      velocity="${drive_vel_max}" />
  </joint>
  <link
    name="middle_left_wheel">
    <inertial>
      <origin
        xyz="4.4851E-10 2.7786E-10 0.0071368"
        rpy="0 0 0" />
      <mass
        value="0.61431" />
      <inertia
        ixx="0.0011197"
        ixy="5.2219E-08"
        ixz="-1.5331E-16"
        iyy="0.0011199"
        iyz="-3.1316E-17"
        izz="0.001892" />
    </inertial>
    <visual>
      <origin
        xyz="0 0 0"
        rpy="0 0 0" />
      <geometry>
        <mesh
          filename="package://osr/meshes/middle_left_wheel.STL" />
      </geometry>
      <material
        name="">
        <color
          rgba="0.62745 0.62745 0.62745 1" />
      </material>
    </visual>
    <collision>
      <origin
        xyz="0 0 0"
        rpy="0 0 0" />
      <geometry>
        <mesh
          filename="package://osr/meshes/middle_left_wheel.STL" />
      </geometry>
    </collision>
  </link>
  <joint
    name="middle_left_drive_joint"
    type="continuous">
    <origin
      xyz="-0.0639545058516444 0.103117089777728 0.436448751635148"
      rpy="0 0 0" />
    <parent
      link="left_bogie" />
    <child
      link="middle_left_wheel" />
    <axis
      xyz="0 0 1" />
    <limit
      effort="${drive_effort_max}"
      velocity="${drive_vel_max}" />
  </joint>
  <link
    name="back_left_corner">
    <inertial>
      <origin
        xyz="0.00012803 -0.058617 -0.078963"
        rpy="0 0 0" />
      <mass
        value="0.17725" />
      <inertia
        ixx="0.00012121"
        ixy="8.0199E-08"
        ixz="1.5423E-07"
        iyy="7.6277E-05"
        iyz="7.7454E-08"
        izz="0.00011786" />
    </inertial>
    <visual>
      <origin
        xyz="0 0 0"
        rpy="0 0 0" />
      <geometry>
        <mesh
          filename="package://osr/meshes/back_left_corner.STL" />
      </geometry>
      <material
        name="">
        <color
          rgba="0.89804 0.91765 0.92941 1" />
      </material>
    </visual>
    <collision>
      <origin
        xyz="0 0 0"
        rpy="0 0 0" />
      <geometry>
        <mesh
          filename="package://osr/meshes/back_left_corner.STL" />
      </geometry>
    </collision>
  </link>
  <joint
    name="back_left_corner_joint"
    type="revolute">
    <origin
      xyz="0.095997370210931 -0.186901909356396 0.0342697447940012"
      rpy="-1.5707963267949 0 1.61170771758594" />
    <parent
      link="left_rocker" />
    <child
      link="back_left_corner" />
    <axis
      xyz="0 0 -1" />
    <limit
      lower="${steer_angle_min}"
      upper="${steer_angle_max}"
      effort="${steer_effort_max}"
      velocity="${steer_vel_max}" />
  </joint>
  <link
    name="back_left_wheel">
    <inertial>
      <origin
        xyz="4.3795E-10 6.9914E-10 0.0071368"
        rpy="0 0 0" />
      <mass
        value="0.61431" />
      <inertia
        ixx="0.0011197"
        ixy="5.7673E-08"
        ixz="-1.2405E-16"
        iyy="0.0011199"
        iyz="1.2035E-16"
        izz="0.001892" />
    </inertial>
    <visual>
      <origin
        xyz="0 0 0"
        rpy="0 0 0" />
      <geometry>
        <mesh
          filename="package://osr/meshes/back_left_wheel.STL" />
      </geometry>
      <material
        name="">
        <color
          rgba="0.62745 0.62745 0.62745 1" />
      </material>
    </visual>
    <collision>
      <origin
        xyz="0 0 0"
        rpy="0 0 0" />
      <geometry>
        <mesh
          filename="package://osr/meshes/back_left_wheel.STL" />
      </geometry>
    </collision>
  </link>
  <joint
    name="back_left_drive_joint"
    type="continuous">
    <origin
      xyz="0.000171808840937315 4.32447939933134E-05 -0.128892240205023"
      rpy="-1.57079632679486 0 0" />
    <parent
      link="back_left_corner" />
    <child
      link="back_left_wheel" />
    <axis
      xyz="0 0 1" />
    <limit
      effort="${drive_effort_max}"
      velocity="${drive_vel_max}" />
  </joint>
  <link
    name="right_rocker">
    <inertial>
      <origin
        xyz="-0.081408 0.0085528 0.03461"
        rpy="0 0 0" />
      <mass
        value="0.54518" />
      <inertia
        ixx="0.00030587"
        ixy="-6.406E-05"
        ixz="-6.7746E-08"
        iyy="0.00071641"
        iyz="-8.8677E-07"
        izz="0.0008578" />
    </inertial>
    <visual>
      <origin
        xyz="0 0 0"
        rpy="0 0 0" />
      <geometry>
        <mesh
          filename="package://osr/meshes/right_rocker.STL" />
      </geometry>
      <material
        name="">
        <color
          rgba="0.89804 0.91765 0.92941 1" />
      </material>
    </visual>
    <collision>
      <origin
        xyz="0 0 0"
        rpy="0 0 0" />
      <geometry>
        <mesh
          filename="package://osr/meshes/right_rocker.STL" />
      </geometry>
    </collision>
  </link>
  <joint
    name="right_rocker_joint"
    type="revolute">
    <origin
      xyz="-0.173736 -0.190624172238515 -0.0594359999999888"
      rpy="-1.5707963267949 0 0" />
    <parent
      link="base_link" />
    <child
      link="right_rocker" />
    <axis
      xyz="0 0 1" />
    <limit
      lower="-0.1"
      upper="0.1"
      effort="0"
      velocity="0" />
  </joint>
  <link
    name="right_bogie">
    <inertial>
      <origin
        xyz="0.10919 -0.034171 -0.35286"
        rpy="0 0 0" />
      <mass
        value="0.5756" />
      <inertia
        ixx="0.00031636"
        ixy="7.664E-05"
        ixz="3.8142E-08"
        iyy="0.00032122"
        iyz="9.6276E-07"
        izz="0.00046272" />
    </inertial>
    <visual>
      <origin
        xyz="0 0 0"
        rpy="0 0 0" />
      <geometry>
        <mesh
          filename="package://osr/meshes/right_bogie.STL" />
      </geometry>
      <material
        name="">
        <color
          rgba="0.89804 0.91765 0.92941 1" />
      </material>
    </visual>
    <collision>
      <origin
        xyz="0 0 0"
        rpy="0 0 0" />
      <geometry>
        <mesh
          filename="package://osr/meshes/right_bogie.STL" />
      </geometry>
    </collision>
  </link>
  <joint
    name="right_rb_axis"
    type="continuous">
    <origin
      xyz="0.188216650413261 0.100148831558874 0.384524249999976"
      rpy="0 0 0" />
    <parent
      link="right_rocker" />
    <child
      link="right_bogie" />
    <axis
      xyz="0 0 -0.999999999999974" />
    <limit
      lower="0"
      upper="0"
      effort="0"
      velocity="0" />
  </joint>
  <link
    name="front_right_corner">
    <inertial>
      <origin
        xyz="-0.00027466 0.05974 -0.078145"
        rpy="0 0 0" />
      <mass
        value="0.1709" />
      <inertia
        ixx="0.00011992"
        ixy="8.0199E-08"
        ixz="-1.5237E-07"
        iyy="7.3812E-05"
        iyz="-7.749E-08"
        izz="0.00011672" />
    </inertial>
    <visual>
      <origin
        xyz="0 0 0"
        rpy="0 0 0" />
      <geometry>
        <mesh
          filename="package://osr/meshes/front_right_corner.STL" />
      </geometry>
      <material
        name="">
        <color
          rgba="0.89804 0.91765 0.92941 1" />
      </material>
    </visual>
    <collision>
      <origin
        xyz="0 0 0"
        rpy="0 0 0" />
      <geometry>
        <mesh
          filename="package://osr/meshes/front_right_corner.STL" />
      </geometry>
    </collision>
  </link>
  <joint
    name="front_right_corner_joint"
    type="revolute">
    <origin
      xyz="0.213307849599925 0.00937420353549007 -0.350130330857906"
      rpy="1.57079655183463 0 0" />
    <parent
      link="right_bogie" />
    <child
      link="front_right_corner" />
    <axis
      xyz="0 0 -1" />
    <limit
      lower="${steer_angle_min}"
      upper="${steer_angle_max}"
      effort="${steer_effort_max}"
      velocity="${steer_vel_max}" />
  </joint>
  <link
    name="front_right_wheel">
    <inertial>
      <origin
        xyz="5.237E-11 -5.0691E-11 -0.0071368"
        rpy="0 0 0" />
      <mass
        value="0.61431" />
      <inertia
        ixx="0.0011197"
        ixy="-5.7673E-08"
        ixz="-1.312E-16"
        iyy="0.0011199"
        iyz="-5.7322E-17"
        izz="0.001892" />
    </inertial>
    <visual>
      <origin
        xyz="0 0 0"
        rpy="0 0 0" />
      <geometry>
        <mesh
          filename="package://osr/meshes/front_right_wheel.STL" />
      </geometry>
      <material
        name="">
        <color
          rgba="0.62745 0.62745 0.62745 1" />
      </material>
    </visual>
    <collision>
      <origin
        xyz="0 0 0"
        rpy="0 0 0" />
      <geometry>
        <mesh
          filename="package://osr/meshes/front_right_wheel.STL" />
      </geometry>
    </collision>
  </link>
  <joint
    name="front_right_drive_joint"
    type="continuous">
    <origin
      xyz="-0.000171808840730647 -4.32447939935632E-05 -0.128892240205185"
      rpy="-1.57079632679494 0 0" />
    <parent
      link="front_right_corner" />
    <child
      link="front_right_wheel" />
    <axis
      xyz="0 0 1" />
    <limit
      effort="${drive_effort_max}"
      velocity="${drive_vel_max}" />
  </joint>
  <link
    name="middle_right_wheel">
    <inertial>
      <origin
        xyz="4.161E-11 3.743E-11 -0.0071368"
        rpy="0 0 0" />
      <mass
        value="0.61431" />
      <inertia
        ixx="0.0011197"
        ixy="-5.2219E-08"
        ixz="-1.6248E-16"
        iyy="0.0011199"
        iyz="3.137E-17"
        izz="0.001892" />
    </inertial>
    <visual>
      <origin
        xyz="0 0 0"
        rpy="0 0 0" />
      <geometry>
        <mesh
          filename="package://osr/meshes/middle_right_wheel.STL" />
      </geometry>
      <material
        name="">
        <color
          rgba="0.62745 0.62745 0.62745 1" />
      </material>
    </visual>
    <collision>
      <origin
        xyz="0 0 0"
        rpy="0 0 0" />
      <geometry>
        <mesh
          filename="package://osr/meshes/middle_right_wheel.STL" />
      </geometry>
    </collision>
  </link>
  <joint
    name="middle_right_drive_joint"
    type="continuous">
    <origin
      xyz="-0.0660270326936359 0.106964536461386 -0.435750229193693"
      rpy="0 0 0" />
    <parent
      link="right_bogie" />
    <child
      link="middle_right_wheel" />
    <axis
      xyz="0 0 1" />
    <limit
      effort="${drive_effort_max}"
      velocity="${drive_vel_max}" />
  </joint>
  <link
    name="back_right_corner">
    <inertial>
      <origin
        xyz="6.896E-05 0.059827 -0.078145"
        rpy="0 0 0" />
      <mass
        value="0.1709" />
      <inertia
        ixx="0.00011992"
        ixy="8.0199E-08"
        ixz="-1.5237E-07"
        iyy="7.3812E-05"
        iyz="-7.749E-08"
        izz="0.00011672" />
    </inertial>
    <visual>
      <origin
        xyz="0 0 0"
        rpy="0 0 0" />
      <geometry>
        <mesh
          filename="package://osr/meshes/back_right_corner.STL" />
      </geometry>
      <material
        name="">
        <color
          rgba="0.89804 0.91765 0.92941 1" />
      </material>
    </visual>
    <collision>
      <origin
        xyz="0 0 0"
        rpy="0 0 0" />
      <geometry>
        <mesh
          filename="package://osr/meshes/back_right_corner.STL" />
      </geometry>
    </collision>
  </link>
  <joint
    name="back_right_corner_joint"
    type="revolute">
    <origin
      xyz="-0.187875925745586 0.0940768587729567 0.0343074274445147"
      rpy="1.57079632679489 0 -0.0306626789685753" />
    <parent
      link="right_rocker" />
    <child
      link="back_right_corner" />
    <axis
      xyz="0 0 -1" />
    <limit
      lower="${steer_angle_min}"
      upper="${steer_angle_max}"
      effort="${steer_effort_max}"
      velocity="${steer_vel_max}" />
  </joint>
  <link
    name="back_right_wheel">
    <inertial>
      <origin
        xyz="2.8141E-11 8.3344E-11 -0.0071368"
        rpy="0 0 0" />
      <mass
        value="0.61431" />
      <inertia
        ixx="0.0011197"
        ixy="-5.7673E-08"
        ixz="-1.5585E-16"
        iyy="0.0011199"
        iyz="-1.1423E-17"
        izz="0.001892" />
    </inertial>
    <visual>
      <origin
        xyz="0 0 0"
        rpy="0 0 0" />
      <geometry>
        <mesh
          filename="package://osr/meshes/back_right_wheel.STL" />
      </geometry>
      <material
        name="">
        <color
          rgba="0.62745 0.62745 0.62745 1" />
      </material>
    </visual>
    <collision>
      <origin
        xyz="0 0 0"
        rpy="0 0 0" />
      <geometry>
        <mesh
          filename="package://osr/meshes/back_right_wheel.STL" />
      </geometry>
    </collision>
  </link>
  <joint
    name="back_right_drive_joint"
    type="continuous">
    <origin
      xyz="0.000171808840730536 4.32447939971159E-05 -0.128892240205185"
      rpy="-1.57079632679494 0 0" />
    <parent
      link="back_right_corner" />
    <child
      link="back_right_wheel" />
    <axis
      xyz="0 0 1" />
    <limit
      effort="${drive_effort_max}"
      velocity="${drive_vel_max}" />
  </joint>
  <link
    name="navcam_vertical">
    <inertial>
      <origin
        xyz="1.4055E-05 -0.00016527 0.0064297"
        rpy="0 0 0" />
      <mass
        value="0.10756" />
      <inertia
        ixx="3.8547E-05"
        ixy="-2.1844E-09"
        ixz="3.861E-11"
        iyy="1.7293E-05"
        iyz="-5.8055E-07"
        izz="3.6809E-05" />
    </inertial>
    <visual>
      <origin
        xyz="0 0 0"
        rpy="0 0 0" />
      <geometry>
        <mesh
          filename="package://osr/meshes/navcam_vertical.STL" />
      </geometry>
      <material
        name="">
        <color
          rgba="0.89804 0.91765 0.92941 1" />
      </material>
    </visual>
    <collision>
      <origin
        xyz="0 0 0"
        rpy="0 0 0" />
      <geometry>
        <mesh
          filename="package://osr/meshes/navcam_vertical.STL" />
      </geometry>
    </collision>
  </link>
  <joint
    name="navcam_vertical_joint"
    type="continuous">
    <origin
      xyz="-0.0594359999999995 0 0.141849999878"
      rpy="0 0 0" />
    <parent
      link="base_link" />
    <child
      link="navcam_vertical" />
    <axis
      xyz="0 0 1" />
  </joint>
  <link
    name="navcam_horiz">
    <inertial>
      <origin
        xyz="0.0035573 0.029356 -0.038973"
        rpy="0 0 0" />
      <mass
        value="0.11944" />
      <inertia
        ixx="0.00011328"
        ixy="-2.4644E-07"
        ixz="-2.2032E-10"
        iyy="0.0001044"
        iyz="-4.0899E-08"
        izz="1.2517E-05" />
    </inertial>
    <visual>
      <origin
        xyz="0 0 0"
        rpy="0 0 0" />
      <geometry>
        <mesh
          filename="package://osr/meshes/navcam_horiz.STL" />
      </geometry>
      <material
        name="">
        <color
          rgba="0.52941 0.54902 0.54902 1" />
      </material>
    </visual>
    <collision>
      <origin
        xyz="0 0 0"
        rpy="0 0 0" />
      <geometry>
        <mesh
          filename="package://osr/meshes/navcam_horiz.STL" />
      </geometry>
    </collision>
  </link>
  <joint
    name="navcam_horiz_joint"
    type="revolute">
    <origin
      xyz="0 -0.0416749999999999 0.0198960872539571"
      rpy="1.57079632679489 0 0" />
    <parent
      link="navcam_vertical" />
    <child
      link="navcam_horiz" />
    <axis
      xyz="0 0 1" />
    <limit
      lower="0"
      upper="0"
      effort="0"
      velocity="0" />
  </joint>

</robot>
